{
  "modified": "2024-06-25T13:33:06Z",
  "published": "2024-06-25T13:33:06Z",
  "schema_version": "1.5.0",
  "id": "MAL-2024-4853",
  "aliases": [
    "SNYK-PYTHON-CAPMONSTERCLOUDCLENT-6513456"
  ],
  "summary": "Malicious code in capmonstercloudclent (PyPI)",
  "details": "\n---\n_-= Per source details. Do not edit below this line.=-_\n",
  "affected": [
    {
      "package": {
        "ecosystem": "PyPI",
        "name": "capmonstercloudclent",
        "purl": "pkg:pypi/capmonstercloudclent"
      },
      "versions": [
        "1.0.0"
      ]
    }
  ],
  "references": [
    {
      "type": "ADVISORY",
      "url": "https://security.snyk.io/vuln/SNYK-PYTHON-CAPMONSTERCLOUDCLENT-6513456"
    },
    {
      "type": "ARTICLE",
      "url": "https://medium.com/checkmarx-security/pypi-is-under-attack-project-creation-and-user-registration-suspended-heres-the-details-c3b6291d4579"
    }
  ],
  "credits": [
    {
      "name": "ReversingLabs",
      "type": "FINDER",
      "contact": [
        "https://www.reversinglabs.com"
      ]
    }
  ],
  "database_specific": {
    "malicious-packages-origins": [
      {
        "id": "RLMA-2024-03633",
        "import_time": "2024-06-28T02:48:25.779605739Z",
        "modified_time": "2024-06-25T13:33:06Z",
        "sha256": "0cd4f2fbde25f27dafd586e30a175030c0e811bb9609f7709565bee091f7a11c",
        "source": "reversing-labs",
        "versions": [
          "1.0.0"
        ]
      }
    ]
  }
}
