{
  "modified": "2024-06-25T13:33:03Z",
  "published": "2024-06-25T13:33:03Z",
  "schema_version": "1.5.0",
  "id": "MAL-2024-4847",
  "aliases": [
    "SNYK-PYTHON-CAPMONSSTERCLOUDCLIENT-6513512"
  ],
  "summary": "Malicious code in capmonsstercloudclient (PyPI)",
  "details": "\n---\n_-= Per source details. Do not edit below this line.=-_\n",
  "affected": [
    {
      "package": {
        "ecosystem": "PyPI",
        "name": "capmonsstercloudclient",
        "purl": "pkg:pypi/capmonsstercloudclient"
      },
      "versions": [
        "1.0.0"
      ]
    }
  ],
  "references": [
    {
      "type": "ADVISORY",
      "url": "https://security.snyk.io/vuln/SNYK-PYTHON-CAPMONSSTERCLOUDCLIENT-6513512"
    },
    {
      "type": "ARTICLE",
      "url": "https://medium.com/checkmarx-security/pypi-is-under-attack-project-creation-and-user-registration-suspended-heres-the-details-c3b6291d4579"
    }
  ],
  "credits": [
    {
      "name": "ReversingLabs",
      "type": "FINDER",
      "contact": [
        "https://www.reversinglabs.com"
      ]
    }
  ],
  "database_specific": {
    "malicious-packages-origins": [
      {
        "id": "RLMA-2024-03627",
        "import_time": "2024-06-28T02:48:25.034243525Z",
        "modified_time": "2024-06-25T13:33:03Z",
        "sha256": "282d55e2237109d4cc10d7da450e54bdf20a92f99cc98ee9b958c0fc6321ab15",
        "source": "reversing-labs",
        "versions": [
          "1.0.0"
        ]
      }
    ]
  }
}
