{
  "modified": "2024-06-25T13:38:10Z",
  "published": "2024-06-25T13:38:10Z",
  "schema_version": "1.5.0",
  "id": "MAL-2024-5481",
  "aliases": [
    "SNYK-PYTHON-PIOLOW-6513686"
  ],
  "summary": "Malicious code in piolow (PyPI)",
  "details": "\n---\n_-= Per source details. Do not edit below this line.=-_\n",
  "affected": [
    {
      "package": {
        "ecosystem": "PyPI",
        "name": "piolow",
        "purl": "pkg:pypi/piolow"
      },
      "versions": [
        "1.0.0"
      ]
    }
  ],
  "references": [
    {
      "type": "ADVISORY",
      "url": "https://security.snyk.io/vuln/SNYK-PYTHON-PIOLOW-6513686"
    },
    {
      "type": "ARTICLE",
      "url": "https://medium.com/checkmarx-security/pypi-is-under-attack-project-creation-and-user-registration-suspended-heres-the-details-c3b6291d4579"
    }
  ],
  "credits": [
    {
      "name": "ReversingLabs",
      "type": "FINDER",
      "contact": [
        "https://www.reversinglabs.com"
      ]
    }
  ],
  "database_specific": {
    "malicious-packages-origins": [
      {
        "id": "RLMA-2024-04263",
        "import_time": "2024-06-28T02:49:39.461341431Z",
        "modified_time": "2024-06-25T13:38:10Z",
        "sha256": "6d8d1512c3ad78993adb7d00ec6fd5880d22eb5c2bbf5b83fa64a0dd98ea1b66",
        "source": "reversing-labs",
        "versions": [
          "1.0.0"
        ]
      }
    ]
  }
}
