{
  "modified": "2024-06-25T13:33:12Z",
  "published": "2024-06-25T13:33:12Z",
  "schema_version": "1.5.0",
  "id": "MAL-2024-4866",
  "aliases": [
    "SNYK-PYTHON-CAPMONSTERCLOUDCLINET-6513709"
  ],
  "summary": "Malicious code in capmonstercloudclinet (PyPI)",
  "details": "\n---\n_-= Per source details. Do not edit below this line.=-_\n",
  "affected": [
    {
      "package": {
        "ecosystem": "PyPI",
        "name": "capmonstercloudclinet",
        "purl": "pkg:pypi/capmonstercloudclinet"
      },
      "versions": [
        "1.0.0"
      ]
    }
  ],
  "references": [
    {
      "type": "ADVISORY",
      "url": "https://security.snyk.io/vuln/SNYK-PYTHON-CAPMONSTERCLOUDCLINET-6513709"
    },
    {
      "type": "ARTICLE",
      "url": "https://medium.com/checkmarx-security/pypi-is-under-attack-project-creation-and-user-registration-suspended-heres-the-details-c3b6291d4579"
    }
  ],
  "credits": [
    {
      "name": "ReversingLabs",
      "type": "FINDER",
      "contact": [
        "https://www.reversinglabs.com"
      ]
    }
  ],
  "database_specific": {
    "malicious-packages-origins": [
      {
        "id": "RLMA-2024-03646",
        "import_time": "2024-06-28T02:48:27.246881892Z",
        "modified_time": "2024-06-25T13:33:12Z",
        "sha256": "dfc5bacaa23f668f2d7737658e1459b1cf1b7eda0bdadff22cf49392ed03912c",
        "source": "reversing-labs",
        "versions": [
          "1.0.0"
        ]
      }
    ]
  }
}
